Workbook

Sheet 4к 9 кл, 3к 11 кл
A1: День недели | B1: Время | C1: Пара | D1: ИСП/П-24-11 ИСП/П-23-09 | E1: ИСП/Р-24-11 ИСП/Р-23-09 | F1: РЕК-23-09 | G1: ФК-24-11 | H1: День недели | I1: Время | J1: Пара
D2: Специальность: Информационные системы и программирование [09.02.07] Программист | E2: Специальность: Информационные системы и программирование [09.02.07] Разработчик веб и мультимедийных приложений | F2: Специальность: Реклама [42.02.01] Базовая | G2: Специальность: Физическая культура [49.02.01] Базовая
D3: КБсп 111п-24 КБо 111п-23 КБо 112п-23 | E3: КБсп 111р-24 КБо 111р-23 | F3: КБо 141-23 | G3: КБсп 221-24
D4: 51 | E4: 26 | F4: 25 | G4: 6
D5: 1 неделя
A6: Понедельник 31.08.2026 | B6: 8:20-09:50 | C6: 1 | H6: =A6 -> Понедельник 31.08.2026 | I6: 8:20-09:50 | J6: 1
B7: 10:00-11:30 | C7: 2 | I7: 10:00-11:30 | J7: 2
B8: 12:05-13:35 | C8: 3 | I8: 12:05-13:35 | J8: 3
B9: 13:45-15:15 | C9: 4 | I9: 13:45-15:15 | J9: 4
B10: 15:25-16:55 | C10: 5 | I10: 15:25-16:55 | J10: 5
A11: Вторник 01.09.2026 | B11: 8:20-09:50 | C11: 1 | H11: =A11 -> Вторник 01.09.2026 | I11: 8:20-09:50 | J11: 1
B12: 10:00-11:30 | C12: 2 | I12: 10:00-11:30 | J12: 2
B13: 12:05-13:35 | C13: 3 | I13: 12:05-13:35 | J13: 3
B14: 13:45-15:15 | C14: 4 | D14: Стандартизация, сертификация и техническое документоведение Соломин Максим Сергеевич ауд. 531 ГК | F14: Техника и технологии рекламного видео Васьковская Татьяна Александровна ауд. 305 | G14: Базовые и новые виды физкультурно-спортивной деятельности Степаненко Юлия Витальевна ауд. 307 | I14: 13:45-15:15 | J14: 4
B15: 15:25-16:55 | C15: 5 | D15: Поддержка и тестирование программных модулей Соломин Максим Сергеевич ауд. 531 ГК | F15: Техника и технологии рекламного видео Васьковская Татьяна Александровна ауд. 305 | G15: Базовые и новые виды физкультурно-спортивной деятельности Степаненко Юлия Витальевна ауд. 307 | I15: 15:25-16:55 | J15: 5
A16: Среда 02.09.2026 | B16: 8:20-09:50 | C16: 1 | F16: Техника и технологии рекламного видео Васьковская Татьяна Александровна ауд. 305 | G16: Теоретические и прикладные аспекты методической работы в области физической культуры и спорта Степаненко Юлия Витальевна ауд. 307 | H16: =A16 -> Среда 02.09.2026 | I16: 8:20-09:50 | J16: 1
B17: 10:00-11:30 | C17: 2 | F17: Техника и технологии рекламного видео Васьковская Татьяна Александровна ауд. 305 | G17: Базовые и новые виды физкультурно-спортивной деятельности Степаненко Юлия Витальевна ауд. 307 | I17: 10:00-11:30 | J17: 2
B18: 12:05-13:35 | C18: 3 | E18: Оптимизация веб-приложений Соломин Максим Сергеевич ауд. 531 ГК | F18: Техника и технологии рекламного видео Васьковская Татьяна Александровна ауд. 305 | G18: Базовые и новые виды физкультурно-спортивной деятельности Степаненко Юлия Витальевна ауд. 307 | I18: 12:05-13:35 | J18: 3
B19: 13:45-15:15 | C19: 4 | D19: Поддержка и тестирование программных модулей Соломин Максим Сергеевич ауд. 531 ГК | E19: Правовое обеспечение профессиональной деятельности Тофан Алина Васильевна ауд. 204 | G19: Возрастная анатомия, физиология и гигиена Гордиенко Ольга Николаевна ауд. 119 ГК | I19: 13:45-15:15 | J19: 4
B20: 15:25-16:55 | C20: 5 | D20: Системное программирование Шамова Анастасия Владимировна ауд. 521 ГК | E20: Оптимизация веб-приложений Соломин Максим Сергеевич ауд. 531 ГК | G20: Возрастная анатомия, физиология и гигиена Гордиенко Ольга Николаевна ауд. 119 ГК | I20: 15:25-16:55 | J20: 5
A21: Четверг 03.09.2026 | B21: 8:20-09:50 | C21: 1 | E21: Проектирование и разработка веб-приложений Соломин Максим Сергеевич ауд. 531 ГК | F21: Техника и технологии рекламного видео Васьковская Татьяна Александровна ауд. 305 | H21: =A21 -> Четверг 03.09.2026 | I21: 8:20-09:50 | J21: 1
B22: 10:00-11:30 | C22: 2 | E22: Проектирование и разработка веб-приложений Соломин Максим Сергеевич ауд. 531 ГК | F22: Техника и технологии рекламного видео Васьковская Татьяна Александровна ауд. 305 | I22: 10:00-11:30 | J22: 2
B23: 12:05-13:35 | C23: 3 | E23: Оптимизация веб-приложений Соломин Максим Сергеевич ауд. 531 ГК | F23: Техника и технологии рекламного видео Васьковская Татьяна Александровна ауд. 305 | I23: 12:05-13:35 | J23: 3
B24: 13:45-15:15 | C24: 4 | D24: Правовое обеспечение профессиональной деятельности Виноградов Никита Владиславович ауд. 303 | E24: Проектирование и разработка веб-приложений Соломин Максим Сергеевич ауд. 531 ГК | F24: Техника и технологии рекламного видео Васьковская Татьяна Александровна ауд. 305 | G24: Базовые и новые виды физкультурно-спортивной деятельности Степаненко Юлия Витальевна ауд. 307 | I24: 13:45-15:15 | J24: 4
B25: 15:25-16:55 | C25: 5 | D25: Стандартизация, сертификация и техническое документоведение Соломин Максим Сергеевич ауд. 531 ГК | E25: Обеспечение безопасности веб-приложений Акишин Максим Витальевич ауд. 210 | G25: Теоретические и прикладные аспекты методической работы в области физической культуры и спорта Степаненко Юлия Витальевна ауд. 307 | I25: 15:25-16:55 | J25: 5
A26: Пятница 04.09.2026 | B26: 8:20-09:50 | C26: 1 | E26: Иностранный язык в профессиональной деятельности Ялышева Александра Геннадьевна ауд. 119 ГК | H26: =A26 -> Пятница 04.09.2026 | I26: 8:20-09:50 | J26: 1
B27: 10:00-11:30 | C27: 2 | E27: Проектирование и разработка веб-приложений Соломин Максим Сергеевич ауд. 531 ГК | F27: Иностранный язык Макеев Данила Сергеевич ауд. 319 ГК | I27: 10:00-11:30 | J27: 2
B28: 12:05-13:35 | C28: 3 | D28: Иностранный язык в профессиональной деятельности Ялышева Александра Геннадьевна ауд. 119 ГК | E28: Проектирование и разработка веб-приложений Соломин Максим Сергеевич ауд. 531 ГК | F28: Иностранный язык Макеев Данила Сергеевич ауд. 319 ГК | G28: Теоретические и прикладные аспекты методической работы в области физической культуры и спорта Степаненко Юлия Витальевна ауд. 307 | I28: 12:05-13:35 | J28: 3
B29: 13:45-15:15 | C29: 4 | D29: Поддержка и тестирование программных модулей Соломин Максим Сергеевич ауд. 531 ГК | F29: Менеджмент и экономические основы рекламной деятельности Гужов Виктор Владимирович ауд. 316 ГК | G29: Базовые и новые виды физкультурно-спортивной деятельности Степаненко Юлия Витальевна ауд. 307 | I29: 13:45-15:15 | J29: 4
B30: 15:25-16:55 | C30: 5 | D30: Стандартизация, сертификация и техническое документоведение Соломин Максим Сергеевич ауд. 531 ГК | F30: Менеджмент и экономические основы рекламной деятельности Гужов Виктор Владимирович ауд. 316 ГК | G30: Теоретические и прикладные аспекты методической работы в области физической культуры и спорта Степаненко Юлия Витальевна ауд. 307 | I30: 15:25-16:55 | J30: 5
A31: Суббота 05.09.2026 | B31: 8:20-09:50 | C31: 1 | F31: Техника и технологии рекламного видео Васьковская Татьяна Александровна ауд. 305 | G31: Физическая культура Наташкин Степан Алексеевич ауд. Спортзал | H31: =A31 -> Суббота 05.09.2026 | I31: 8:20-09:50 | J31: 1
B32: 10:00-11:30 | C32: 2 | D32: Системное программирование Шамова Анастасия Владимировна ауд. 520 ГК | F32: Техника и технологии рекламного видео Васьковская Татьяна Александровна ауд. 305 | G32: Иностранный язык в профессиональной деятельности Макеев Данила Сергеевич ауд. 319 ГК | I32: 10:00-11:30 | J32: 2
B33: 12:05-13:35 | C33: 3 | D33: Поддержка и тестирование программных модулей Соломин Максим Сергеевич ауд. 505 ГК | F33: Техника и технологии рекламного видео Васьковская Татьяна Александровна ауд. 305 | I33: 12:05-13:35 | J33: 3
B34: 13:45-15:15 | C34: 4 | E34: Оптимизация веб-приложений Соломин Максим Сергеевич ауд. 505 ГК | F34: Менеджмент и экономические основы рекламной деятельности Гужов Виктор Владимирович ауд. 316 ГК | I34: 13:45-15:15 | J34: 4
B35: 15:25-16:55 | C35: 5 | E35: Стандартизация, сертификация и техническое документоведение Соломин Максим Сергеевич ауд. 505 ГК | F35: Менеджмент и экономические основы рекламной деятельности Гужов Виктор Владимирович ауд. 316 ГК | I35: 15:25-16:55 | J35: 5

Sheet 3к 9 кл, 2к 11 кл
A1: День недели | B1: Время | C1: Пара | D1: БАД-25-11 БАД-24-09 | E1: ИСП/Р-25-11 ИСП/Р-24-09 | F1: КСК-25-11 КСК-24-09 | G1: ОДЛ-25-11 ОДЛ-24-09 | H1: ТД-25-11 ТД-24-09 | I1: ЮР/са-25-11 ЮР/са-24-09 | J1: ЮР/со-25-11 ЮР/со-24-09 | K1: ФИН-24-09 | L1: ФИН-25-11 | M1: РЕК-24-09 | N1: РЕК-25-11 | O1: БУХ-24-09 | P1: БУХ-25-11 | Q1: ИСП/П-24-09 | R1: День недели | S1: Время | T1: Пара
D2: Специальность: Банковское дело [38.02.07] Базовая | E2: Специальность: Информационные системы и программирование [09.02.07] Разработчик веб и мультимедийных приложений | F2: Специальность: Компьютерные системы и комплексы [09.02.01] Базовая | G2: Специальность: Операционная деятельность в логистике [38.02.03] Базовая | H2: Специальность: Торговое дело [38.02.08] Базовая | I2: Специальность: Юриспруденция [40.02.04] Базовая | J2: Специальность: Юриспруденция [40.02.04] Базовая | K2: Специальность: Финансы [38.02.06] Базовая | L2: Специальность: Финансы [38.02.06] Базовая | M2: Специальность: Реклама [42.02.01] Базовая | N2: Специальность: Реклама [42.02.01] Базовая | O2: Специальность: Экономика и бухгалтерский учет (по отраслям) [38.02.01] Базовая | P2: Специальность: Экономика и бухгалтерский учет (по отраслям) [38.02.01] Базовая | Q2: Специальность: Информационные системы и программирование [09.02.07] Программист
D3: к/о/к БАД 25-11 КБо 41-24 | E3: к/о/к ИСП/р 25-11 КБо 111р-24 | F3: к/о/к КСК 25-11 КБо 191-24 | G3: к/о/к ОДЛ 25-11 КБо 121-24 | H3: к/о/к ТД 25-11 КБо 211-24 | I3: к/о/к ЮР/са 25-11 КБо 232са-24 | J3: к/о/к ЮР/со 25-11 КБо 231со-24 | K3: КБо 21-24 | L3: к/о/к ФИН 25-11 | M3: КБо 141-24 | N3: к/о/к РЕК 25-11 | O3: КБо 51-24 | P3: к/о/к БУХ 25-11 | Q3: КБо 111п-24
D4: 29 | E4: 31 | F4: 13 | G4: 49 | H4: 46 | I4: 37 | J4: 33 | K4: 27 | L4: 12 | M4: 56 | N4: 15 | O4: 7 | P4: 6 | Q4: 33
D5: ='4к 9 кл, 3к 11 кл'!D5:G5 -> 1 неделя
A6: ='4к 9 кл, 3к 11 кл'!A6:A10 -> Понедельник 31.08.2026 | B6: 8:20-09:50 | C6: 1 | R6: ='4к 9 кл, 3к 11 кл'!A6:A10 -> Понедельник 31.08.2026 | S6: 8:20-09:50 | T6: 1
B7: 10:00-11:30 | C7: 2 | S7: 10:00-11:30 | T7: 2
B8: 12:05-13:35 | C8: 3 | S8: 12:05-13:35 | T8: 3
B9: 13:45-15:15 | C9: 4 | S9: 13:45-15:15 | T9: 4
B10: 15:25-16:55 | C10: 5 | S10: 15:25-16:55 | T10: 5
A11: ='4к 9 кл, 3к 11 кл'!A11:A15 -> Вторник 01.09.2026 | B11: 8:20-09:50 | C11: 1 | R11: ='4к 9 кл, 3к 11 кл'!A11:A15 -> Вторник 01.09.2026 | S11: 8:20-09:50 | T11: 1
B12: 10:00-11:30 | C12: 2 | S12: 10:00-11:30 | T12: 2
B13: 12:05-13:35 | C13: 3 | S13: 12:05-13:35 | T13: 3
B14: 13:45-15:15 | C14: 4 | D14: Кассовые операции банка Протасова Людмила Валерьевна ауд. 107 | G14: Транспортная логистика Петракова Екатерина Валерьевна ауд. 206 | H14: Оценка качества и основы экспертизы потребительских товаров Митерова Елена Валерьевна ауд. 105 | I14: Уголовный процесс Тофан Алина Васильевна ауд. 204 | J14: Гражданское право Рянжина Юлия Андреевна ауд. 201 | K14: Основы финансового планирования в государственных (муниципальных) учреждениях Давтян Анна Юрьевна ауд. 102 | N14: Стратегии продвижения бренда в сети Интернет Любиченко Анна Андреевна ауд. 303 | S14: 13:45-15:15 | T14: 4
B15: 15:25-16:55 | C15: 5 | D15: Кассовые операции банка Протасова Людмила Валерьевна ауд. 107 | F15: Основы проектирования цифровой техники Шамов Артём Варельевич ауд. 118 ГК | G15: Транспортная логистика Петракова Екатерина Валерьевна ауд. 206 | H15: Оценка качества и основы экспертизы потребительских товаров Митерова Елена Валерьевна ауд. 105 | I15: Уголовное право Рянжина Юлия Андреевна ауд. 201 | J15: Уголовный процесс Тофан Алина Васильевна ауд. 204 | K15: Финансово-экономический механизм государственных закупок Давтян Анна Юрьевна ауд. 102 | N15: Разработка и реализация рекламных кампаний бренда в сети Интернет инструм. поиск. оптимизации, кон.-медий. рек. и маркет. в социальных сетях Любиченко Анна Андреевна ауд. 303 | S15: 15:25-16:55 | T15: 5
A16: ='4к 9 кл, 3к 11 кл'!A16:A20 -> Среда 02.09.2026 | B16: 8:20-09:50 | C16: 1 | K16: Финансы организаций Давтян Анна Юрьевна ауд. 102 | N16: Стратегии продвижения бренда в сети Интернет Любиченко Анна Андреевна ауд. 323 ГК | O16: Основы предпринимательской деятельности Гужов Виктор Владимирович ауд. 320 ГК | R16: ='4к 9 кл, 3к 11 кл'!A16:A20 -> Среда 02.09.2026 | S16: 8:20-09:50 | T16: 1
B17: 10:00-11:30 | C17: 2 | D17: Бухгалтерский учет Протасова Людмила Валерьевна ауд. 107 | E17: Физическая культура/Адаптивная физическая культура Заборских Артём Эдуардович ауд. спортзал | H17: Управление ассортиментом товаров Митерова Елена Валерьевна ауд. ВЕБИНАР | J17: Уголовный процесс Тофан Алина Васильевна ауд. 204 | K17: Финансы организаций Давтян Анна Юрьевна ауд. 102 | N17: Разработка и реализация рекламных кампаний бренда в сети Интернет инструм. поиск. оптимизации, кон.-медий. рек. и маркет. в социальных сетях Любиченко Анна Андреевна ауд. 323 ГК | O17: Основы предпринимательской деятельности Гужов Виктор Владимирович ауд. 320 ГК | S17: 10:00-11:30 | T17: 2
B18: 12:05-13:35 | C18: 3 | D18: Бухгалтерский учет Протасова Людмила Валерьевна ауд. 107 | E18: Основы философии Набиуллина Диляра Альбертовна ауд. 104 | G18: Моделирование логистических систем Петракова Екатерина Валерьевна ауд. 206 | H18: Оценка качества и основы экспертизы потребительских товаров Митерова Елена Валерьевна ауд. ВЕБИНАР | J18: Уголовный процесс Тофан Алина Васильевна ауд. 204 | K18: Основы предпринимательской деятельности Гужов Виктор Владимирович ауд. 320 ГК | L18: Налоги и налогообложение Давтян Анна Юрьевна ауд. 102 | N18: Разработка и реализация рекламных кампаний бренда в сети Интернет инструм. поиск. оптимизации, кон.-медий. рек. и маркет. в социальных сетях Любиченко Анна Андреевна ауд. 323 ГК | S18: 12:05-13:35 | T18: 3
B19: 13:45-15:15 | C19: 4 | D19: Иностранный язык в профессиональной деятельности Ялышева Александра Геннадьевна ауд. 322 ГК | E19: Основы философии Набиуллина Диляра Альбертовна ауд. 104 | F19: Физическая культура/Адаптивная физическая культура Заборских Артём Эдуардович ауд. Спортзал | G19: Транспортная логистика Петракова Екатерина Валерьевна ауд. 206 | H19: Оценка качества и основы экспертизы потребительских товаров Митерова Елена Валерьевна ауд. ВЕБИНАР | I19: Судоустройство и правоохранительные органы Виноградов Никита Владиславович ауд. 303 | J19: Право социального обеспечения Рянжина Юлия Андреевна ауд. 201 | K19: Финансовый контроль деятельности экономического субъекта Протасова Людмила Валерьевна ауд. 107 | L19: Налоговый контроль и администрирование Давтян Анна Юрьевна ауд. 102 | M19: Разработка и реализация рекламных кампаний бренда в сети Интернет инструм. поиск. оптимизации, кон.-медий. рек. и маркет. в социальных сетях Репина Ольга Владимировна ауд. 326 ГК | N19: Информационные технологии в профессиональной деятельности Акишин Максим Витальевич ауд. 210 | Q19: Технология разработки программного обеспечения Шамова Анастасия Владимировна ауд. ВЕБИНАР | S19: 13:45-15:15 | T19: 4
B20: 15:25-16:55 | C20: 5 | E20: Проектирование и разработка интерфейсов пользователя Чагиров Артур Олегович ауд. 109 ГК | F20: Иностранный язык в профессиональной деятельности Ялышева Александра Геннадьевна ауд. 322 ГК | G20: Транспортная логистика Петракова Екатерина Валерьевна ауд. 206 | I20: Уголовный процесс Тофан Алина Васильевна ауд. 204 | J20: Уголовное право Рянжина Юлия Андреевна ауд. 201 | K20: Основы финансового планирования в государственных (муниципальных) учреждениях Давтян Анна Юрьевна ауд. 102 | M20: Информационные технологии в профессиональной деятельности Акишин Максим Витальевич ауд. 210 | N20: Иностранный язык в профессиональной деятельности Макеев Данила Сергеевич ауд. 319 ГК | Q20: Экономика отрасли Митерова Елена Валерьевна ауд. ВЕБИНАР | S20: 15:25-16:55 | T20: 5
A21: ='4к 9 кл, 3к 11 кл'!A21:A25 -> Четверг 03.09.2026 | B21: 8:20-09:50 | C21: 1 | F21: Разработка и прототипирование цифровых систем Шамов Артём Варельевич ауд. 118 ГК | Q21: Менеджмент в профессиональной деятельности Гужов Виктор Владимирович ауд. 320 ГК | R21: ='4к 9 кл, 3к 11 кл'!A21:A25 -> Четверг 03.09.2026 | S21: 8:20-09:50 | T21: 1
B22: 10:00-11:30 | C22: 2 | E22: Экономика отрасли Митерова Елена Валерьевна ауд. 105 | F22: Основы электротехники и электронной техники Шамов Артём Варельевич ауд. 118 ГК | G22: Моделирование логистических систем Петракова Екатерина Валерьевна ауд. 206 | M22: Разработка и реализация рекламных кампаний бренда в сети Интернет инструм. поиск. оптимизации, кон.-медий. рек. и маркет. в социальных сетях Репина Ольга Владимировна ауд. 326 ГК | Q22: Менеджмент в профессиональной деятельности Гужов Виктор Владимирович ауд. 320 ГК | S22: 10:00-11:30 | T22: 2
B23: 12:05-13:35 | C23: 3 | E23: Экономика отрасли Митерова Елена Валерьевна ауд. 105 | F23: Метрология и электротехнические измерения Шамов Артём Варельевич ауд. 118 ГК | G23: Транспортная логистика Петракова Екатерина Валерьевна ауд. 206 | H23: Основы предпринимательства Гужов Виктор Владимирович ауд. 320 ГК | L23: Основы финансового планирования в организациях Давтян Анна Юрьевна ауд. 102 | M23: Разработка и реализация рекламных кампаний бренда в сети Интернет инструм. поиск. оптимизации, кон.-медий. рек. и маркет. в социальных сетях Репина Ольга Владимировна ауд. 326 ГК | Q23: Численные методы Абрамова Татьяна Викторовна ауд. 202 ГК | S23: 12:05-13:35 | T23: 3
B24: 13:45-15:15 | C24: 4 | D24: Бухгалтерский учет Протасова Людмила Валерьевна ауд. 107 | E24: Менеджмент в профессиональной деятельности Гужов Виктор Владимирович ауд. 320 ГК | F24: Основы проектирования цифровой техники Шамов Артём Варельевич ауд. 118 ГК | G24: Логистика сервисного обслуживания Верилов Александр Анатольевич ауд. 319 ГК | H24: Управление ассортиментом товаров Митерова Елена Валерьевна ауд. 105 | I24: Уголовный процесс Тофан Алина Васильевна ауд. 204 | J24: Уголовное право Рянжина Юлия Андреевна ауд. 201 | K24: Иностранный язык в профессиональной деятельности Макеев Данила Сергеевич ауд. 316 ГК | L24: Налоги и налогообложение Давтян Анна Юрьевна ауд. 102 | M24: Информационные технологии в профессиональной деятельности Акишин Максим Витальевич ауд. 210 | N24: Стратегии продвижения бренда в сети Интернет Любиченко Анна Андреевна ауд. 323 ГК | Q24: Инструментальные средства разработки программного обеспечения Шамова Анастасия Владимировна ауд. 521 ГК | S24: 13:45-15:15 | T24: 4
B25: 15:25-16:55 | C25: 5 | D25: Бухгалтерский учет Протасова Людмила Валерьевна ауд. 107 | E25: Проектирование и разработка интерфейсов пользователя Чагиров Артур Олегович ауд. 505 ГК | F25: Основы электротехники и электронной техники Шамов Артём Варельевич ауд. 118 ГК | H25: Основы предпринимательства Гужов Виктор Владимирович ауд. 320 ГК | I25: Судебное делопроизводство Виноградов Никита Владиславович ауд. 303 | J25: Гражданское право Рянжина Юлия Андреевна ауд. 201 | K25: Финансово-экономический механизм государственных закупок Давтян Анна Юрьевна ауд. 102 | L25: Иностранный язык в профессиональной деятельности Макеев Данила Сергеевич ауд. 316 ГК | M25: Основы композиции, рисунка, живописи в рекламе Васьковская Татьяна Александровна ауд. 305 | N25: Разработка и реализация рекламных кампаний бренда в сети Интернет инструм. поиск. оптимизации, кон.-медий. рек. и маркет. в социальных сетях Любиченко Анна Андреевна ауд. 323 ГК | Q25: Экономика отрасли Митерова Елена Валерьевна ауд. 105 | S25: 15:25-16:55 | T25: 5
A26: ='4к 9 кл, 3к 11 кл'!A26:A30 -> Пятница 04.09.2026 | B26: 8:20-09:50 | C26: 1 | G26: Логистика сервисного обслуживания Верилов Александр Анатольевич ауд. 320 ГК | I26: Гражданское право Рянжина Юлия Андреевна ауд. 201 | K26: Основы предпринимательской деятельности Гужов Виктор Владимирович ауд. 316 ГК | N26: Рекламная деятельность Лебедева Катерина Владимировна ауд. ВЕБИНАР | R26: ='4к 9 кл, 3к 11 кл'!A26:A30 -> Пятница 04.09.2026 | S26: 8:20-09:50 | T26: 1
B27: 10:00-11:30 | C27: 2 | G27: Логистика сервисного обслуживания Верилов Александр Анатольевич ауд. 320 ГК | I27: Судоустройство и правоохранительные органы Виноградов Никита Владиславович ауд. 303 | J27: Гражданское право Рянжина Юлия Андреевна ауд. 201 | K27: Финансовый контроль деятельности экономического субъекта Протасова Людмила Валерьевна ауд. 107 | N27: Рекламная деятельность Лебедева Катерина Владимировна ауд. ВЕБИНАР | S27: 10:00-11:30 | T27: 2
B28: 12:05-13:35 | C28: 3 | E28: Основы проектирования баз данных Сулейманов Ильмир Ильдусович ауд. 108 ГК | G28: Логистика сервисного обслуживания Верилов Александр Анатольевич ауд. 320 ГК | I28: Судебное делопроизводство Виноградов Никита Владиславович ауд. 303 | J28: Право социального обеспечения Рянжина Юлия Андреевна ауд. 201 | K28: Финансовый контроль деятельности экономического субъекта Протасова Людмила Валерьевна ауд. 107 | S28: 12:05-13:35 | T28: 3
B29: 13:45-15:15 | C29: 4 | E29: Численные методы Абрамова Татьяна Викторовна ауд. 202 ГК | F29: Разработка и прототипирование цифровых систем Шамов Артём Варельевич ауд. 118 ГК | H29: Оценка качества и основы экспертизы потребительских товаров Митерова Елена Валерьевна ауд. 105 | I29: Уголовное право Рянжина Юлия Андреевна ауд. 201 | J29: Судоустройство и правоохранительные органы Виноградов Никита Владиславович ауд. 303 | S29: 13:45-15:15 | T29: 4
B30: 15:25-16:55 | C30: 5 | E30: Численные методы Абрамова Татьяна Викторовна ауд. 202 ГК | F30: Разработка прикладных приложений Шамов Артём Варельевич ауд. 118 ГК | H30: Оценка качества и основы экспертизы потребительских товаров Митерова Елена Валерьевна ауд. 105 | I30: Гражданское право Рянжина Юлия Андреевна ауд. 201 | J30: Судоустройство и правоохранительные органы Виноградов Никита Владиславович ауд. 303 | S30: 15:25-16:55 | T30: 5
A31: ='4к 9 кл, 3к 11 кл'!A31:A35 -> Суббота 05.09.2026 | B31: 8:20-09:50 | C31: 1 | F31: Основы электротехники и электронной техники Шамов Артём Варельевич ауд. 118 ГК | K31: Финансы организаций Давтян Анна Юрьевна ауд. 102 | R31: ='4к 9 кл, 3к 11 кл'!A31:A35 -> Суббота 05.09.2026 | S31: 8:20-09:50 | T31: 1
B32: 10:00-11:30 | C32: 2 | E32: Проектирование и разработка интерфейсов пользователя Чагиров Артур Олегович ауд. 507 ГК | F32: Основы проектирования цифровой техники Шамов Артём Варельевич ауд. 118 ГК | G32: Физическая культура Наташкин Степан Алексеевич ауд. Спортзал | I32: Информационные технологии в юридической деятельности Туркин Дмитрий Валерьевич ауд. 109 ГК | K32: Основы финансового планирования в государственных (муниципальных) учреждениях Давтян Анна Юрьевна ауд. 102 | Q32: Иностранный язык в профессиональной деятельности Ялышева Александра Геннадьевна ауд. 303 | S32: 10:00-11:30 | T32: 2
B33: 12:05-13:35 | C33: 3 | E33: Основы проектирования баз данных Сулейманов Ильмир Ильдусович ауд. 108 ГК | F33: Разработка и прототипирование цифровых систем Шамов Артём Варельевич ауд. 118 ГК | G33: Иностранный язык в профессиональной деятельности Макеев Данила Сергеевич ауд. 319 ГК | H33: Физическая культура Наташкин Степан Алексеевич ауд. Спортзал | I33: Информационные технологии в юридической деятельности Туркин Дмитрий Валерьевич ауд. 109 ГК | L33: Налоги и налогообложение Давтян Анна Юрьевна ауд. 102 | M33: Разработка и реализация рекламных кампаний бренда в сети Интернет инструм. поиск. оптимизации, кон.-медий. рек. и маркет. в социальных сетях Репина Ольга Владимировна ауд. 201 | N33: Стратегии продвижения бренда в сети Интернет Любиченко Анна Андреевна ауд. 314 | O33: Иностранный язык в профессиональной деятельности Ялышева Александра Геннадьевна ауд. 303 | Q33: Инструментальные средства разработки программного обеспечения Шамова Анастасия Владимировна ауд. 520 ГК | S33: 12:05-13:35 | T33: 3
B34: 13:45-15:15 | C34: 4 | E34: Основы проектирования баз данных Сулейманов Ильмир Ильдусович ауд. 108 ГК | F34: Разработка прикладных приложений Шамов Артём Варельевич ауд. 118 ГК | G34: Моделирование логистических систем Петракова Екатерина Валерьевна ауд. 206 | H34: Технология продаж потребительских товаров и координация работы с клиентами Верилов Александр Анатольевич ауд. 320 ГК | I34: Иностранный язык в профессиональной деятельности Макеев Данила Сергеевич ауд. 319 ГК | J34: Информационные технологии в юридической деятельности Туркин Дмитрий Валерьевич ауд. 109 ГК | L34: Основы финансового планирования в организациях Давтян Анна Юрьевна ауд. 102 | M34: Основы композиции, рисунка, живописи в рекламе Васьковская Татьяна Александровна ауд. 305 | N34: Физическая культура Наташкин Степан Алексеевич ауд. Спортзал | O34: Иностранный язык в профессиональной деятельности Ялышева Александра Геннадьевна ауд. 303 | Q34: Технология разработки программного обеспечения Шамова Анастасия Владимировна ауд. 520 ГК | S34: 13:45-15:15 | T34: 4
B35: 15:25-16:55 | C35: 5 | E35: Основы проектирования баз данных Сулейманов Ильмир Ильдусович ауд. 108 ГК | G35: Транспортная логистика Петракова Екатерина Валерьевна ауд. 206 | H35: Технология продаж потребительских товаров и координация работы с клиентами Верилов Александр Анатольевич ауд. 320 ГК | J35: Иностранный язык в профессиональной деятельности Макеев Данила Сергеевич ауд. 319 ГК | L35: Финансово-экономический механизм закупок для государственных, муниципальных и корпоративных нужд Давтян Анна Юрьевна ауд. 102 | N35: Основы композиции, рисунка, живописи в рекламе Васьковская Татьяна Александровна ауд. 305 | S35: 15:25-16:55 | T35: 5

Sheet 2к 9 кл, 1к 11 кл
A1: День недели | B1: Время | C1: Пара | D1: БАД 26-11 БАД-25-09 | E1: БУХ 26-11 БУХ-25-09 | F1: ДИЗ 26-11 | G1: ДО 26-11 | H1: ОДЛ 26-11 ОДЛ-25-09 | I1: ТД 26-11 ТД-25-09 | J1: ФИН 26-11 ФИН-25-09 | K1: ЮР/со 26-11 ЮР/со-25-09 | L1: РЕК 26-11 РЕК-25-09 | M1: ПВНК 26-11 ПВНК-25-09 | N1: ОИБАС 26-11 | O1: КСК 26-11 КСК-25-09 | P1: ЮР/са 26-11 ЮР/са-25-09 | Q1: День недели | R1: Время | S1: Пара
D2: Специальность: Банковское дело [38.02.07] Базовая | E2: Специальность: Экономика и бухгалтерский учет (по отраслям) [38.02.01] Базовая | F2: Специальность: Дизайн (по отраслям) [54.02.01] Базовая | G2: Специальность: Дошкольное образование [44.02.01] Базовая | H2: Специальность: Операционная деятельность в логистике [38.02.03] Базовая | I2: Специальность: Торговое дело [38.02.08] Базовая | J2: Специальность: Финансы [38.02.06] Базовая | K2: Специальность: Юриспруденция [40.02.04] Базовая | L2: Специальность: Реклама [42.02.01] Базовая | M2: Специальность: Преподавание в начальных классах [44.02.02] Базовая | N2: Специальность: Обеспечение информационной безопасности автоматизированных систем [10.02.05] Базовая | O2: Специальность: Компьютерные системы и комплексы [09.02.01] Базовая | P2: Специальность: Юриспруденция [40.02.04] Базовая
D3: к/о/к БАД 26-11 к/о/к БАД 25-09 | E3: к/о/к БУХ 26-11 к/о/к БУХ 25-09 | H3: к/о/к ОДЛ 26-11 к/о/к ОДЛ 25-09.2 | I3: к/о/к ТД 26-11 к/о/к ТД 25-09.1 | J3: к/о/к ФИН 26-11 к/о/к ФИН 25-09 | K3: к/о/к ЮР/со 26-11 к/о/к ЮР/со 25-09 | L3: к/о/к РЕК 26-11 к/о/к РЕК 25-09.3 | M3: к/о/к ПВНК 26-11 к/о/к ПВНК 25-09 | O3: к/о/к КСК 26-11 к/о/к КСК 25-09 | P3: к/о/к ЮР/са 26-11 к/о/к ЮР/са 25-09.2
D4: 23 | E4: 16 | F4: 25 | G4: 25 | H4: 26 | I4: 32 | J4: 27 | K4: 12 | L4: 18 | M4: 15 | N4: 25 | O4: 5 | P4: 20
D5: ='4к 9 кл, 3к 11 кл'!D5:G5 -> 1 неделя
A6: ='4к 9 кл, 3к 11 кл'!A6:A10 -> Понедельник 31.08.2026 | B6: 8:20-09:50 | C6: 1 | Q6: ='4к 9 кл, 3к 11 кл'!A6:A10 -> Понедельник 31.08.2026 | R6: 8:20-09:50 | S6: 1
B7: 10:00-11:30 | C7: 2 | R7: 10:00-11:30 | S7: 2
B8: 12:05-13:35 | C8: 3 | R8: 12:05-13:35 | S8: 3
B9: 13:45-15:15 | C9: 4 | R9: 13:45-15:15 | S9: 4
B10: 15:25-16:55 | C10: 5 | R10: 15:25-16:55 | S10: 5
A11: ='4к 9 кл, 3к 11 кл'!A11:A15 -> Вторник 01.09.2026 | B11: 8:20-09:50 | C11: 1 | Q11: ='4к 9 кл, 3к 11 кл'!A11:A15 -> Вторник 01.09.2026 | R11: 8:20-09:50 | S11: 1
B12: 10:00-11:30 | C12: 2 | R12: 10:00-11:30 | S12: 2
B13: 12:05-13:35 | C13: 3 | R13: 12:05-13:35 | S13: 3
B14: 13:45-15:15 | C14: 4 | R14: 13:45-15:15 | S14: 4
B15: 15:25-16:55 | C15: 5 | R15: 15:25-16:55 | S15: 5
A16: ='4к 9 кл, 3к 11 кл'!A16:A20 -> Среда 02.09.2026 | B16: 8:20-09:50 | C16: 1 | E16: Статистика Блесткина Ольга Владимировна ауд. 321 ГК | G16: Теоретические и методические основы физического воспитания и развития детей раннего и дошкольного возраста Глущенко Марина Валерьевна ауд. 314 | L16: Основы бережливого производства Петракова Екатерина Валерьевна ауд. 206 | O16: Основы алгоритмизации и программирования Шамов Артём Варельевич ауд. 507 ГК | P16: Уголовное право Рянжина Юлия Андреевна ауд. 201 | Q16: ='4к 9 кл, 3к 11 кл'!A16:A20 -> Среда 02.09.2026 | R16: 8:20-09:50 | S16: 1
B17: 10:00-11:30 | C17: 2 | E17: Экономика организации Блесткина Ольга Владимировна ауд. 321 ГК | F17: Материаловедение Лебедева Катерина Владимировна ауд. 308 | G17: Теоретические и методические основы физического воспитания и развития детей раннего и дошкольного возраста Глущенко Марина Валерьевна ауд. 314 | H17: Элементы высшей математики Абрамова Татьяна Викторовна ауд. 202 ГК | I17: Организация торгово-сбытовой деятельности на внутреннем и внешнем рынках Репина Ольга Владимировна ауд. 326 ГК | K17: Судоустройство и правоохранительные органы Виноградов Никита Владиславович ауд. 303 | L17: Основы бережливого производства Петракова Екатерина Валерьевна ауд. 206 | O17: Основы алгоритмизации и программирования Шамов Артём Варельевич ауд. 507 ГК | P17: Уголовное право Рянжина Юлия Андреевна ауд. 201 | R17: 10:00-11:30 | S17: 2
B18: 12:05-13:35 | C18: 3 | D18: Финансы организации Блесткина Ольга Владимировна ауд. 321 ГК | E18: Мастер-класс с работодателем по специальности «Экономика и бухгалтерский учет», «Финансы» ООО «Русаудит» Смирнова Светлана Заместитель руководителя ауд. 117 ГК | F18: Материаловедение Лебедева Катерина Владимировна ауд. 308 | G18: Основы возрастной и педагогической психологии Глущенко Марина Валерьевна ауд. 314 | H18: Элементы высшей математики Абрамова Татьяна Викторовна ауд. 202 ГК | I18: Организация торгово-сбытовой деятельности на внутреннем и внешнем рынках Репина Ольга Владимировна ауд. 326 ГК | J18: Мастер-класс с работодателем по специальности «Экономика и бухгалтерский учет», «Финансы» ООО «Русаудит» Смирнова Светлана Заместитель руководителя ауд. 117 ГК | K18: Судоустройство и правоохранительные органы Виноградов Никита Владиславович ауд. 303 | L18: Физическая культура Наташкин Степан Алексеевич ауд. Спортзал | O18: Настройка и обеспечение функционирования программных средств компьютерных систем и комплексов Шамов Артём Варельевич ауд. 507 ГК | P18: Конституционное право России Рянжина Юлия Андреевна ауд. 201 | R18: 12:05-13:35 | S18: 3
B19: 13:45-15:15 | C19: 4 | D19: История России Гоголев Николай Борисович ауд. 431 ГК | E19: Статистика Блесткина Ольга Владимировна ауд. 321 ГК | F19: Дизайн-проектирование Любиченко Анна Андреевна ауд. 323 ГК | G19: Физическая культура Наташкин Степан Алексеевич ауд. спортзал | H19: Русский язык и культура речи Митерова Евгения Анатольевна ауд. 108 | I19: История России Григорян Виталий Дмитриевич ауд. 312 | J19: История России Винокур Константин Владимирович ауд. 315 ГК | L19: Основы композиции, рисунка, живописи в рекламе Васьковская Татьяна Александровна ауд. 305 | M19: Теоретические основы организации обучения в начальных классах Гарманова Анна Юрьевна ауд. 316 ГК | O19: Информационные технологии Туркин Дмитрий Валерьевич ауд. 509 ГК | R19: 13:45-15:15 | S19: 4
B20: 15:25-16:55 | C20: 5 | D20: Технология выполнения работ по должности служащего 20002 Агент банка Протасова Людмила Валерьевна ауд. 107 | E20: Экономика организации Блесткина Ольга Владимировна ауд. 321 ГК | F20: Основы проектной и компьютерной графики Любиченко Анна Андреевна ауд. 323 ГК | G20: История России Гоголев Николай Борисович ауд. 431 ГК | H20: Физическая культура Наташкин Степан Алексеевич ауд. Спортзал | J20: Правовое и документационное обеспечение контрольно-надзорной деятельности в финансовой сфере Виноградов Никита Владиславович ауд. 303 | L20: Русский язык и культура речи Митерова Евгения Анатольевна ауд. 108 | M20: Русский язык и культура профессиональной коммуникации педагога Гарманова Анна Юрьевна ауд. 316 ГК | O20: Техническое обслуживание и ремонт аппаратной части компьютерных систем и комплексов Шамов Артём Варельевич ауд. 507 ГК | R20: 15:25-16:55 | S20: 5
A21: ='4к 9 кл, 3к 11 кл'!A21:A25 -> Четверг 03.09.2026 | B21: 8:20-09:50 | C21: 1 | H21: Основы логистической деятельности Верилов Александр Анатольевич ауд. 319 ГК | J21: Статистика Давтян Анна Юрьевна ауд. 102 | K21: Уголовное право Рянжина Юлия Андреевна ауд. 201 | M21: Основы педагогики Глущенко Марина Валерьевна ауд. 110 | P21: Судоустройство и правоохранительные органы Виноградов Никита Владиславович ауд. 303 | Q21: ='4к 9 кл, 3к 11 кл'!A21:A25 -> Четверг 03.09.2026 | R21: 8:20-09:50 | S21: 1
B22: 10:00-11:30 | C22: 2 | D22: Основы бережливого производства Блесткина Ольга Владимировна ауд. 321 ГК | E22: Основы бухгалтерского учета Протасова Людмила Валерьевна ауд. 107 | F22: Основы проектной и компьютерной графики Любиченко Анна Андреевна ауд. 323 ГК | H22: Складская логистика Верилов Александр Анатольевич ауд. 319 ГК | J22: Статистика Давтян Анна Юрьевна ауд. 102 | K22: Уголовное право Рянжина Юлия Андреевна ауд. 201 | L22: История России Григорян Виталий Дмитриевич ауд. 312 | M22: Теоретические основы начального курса математики с методикой преподавания Глущенко Марина Валерьевна ауд. 110 | O22: Операционные системы и среды Сулейманов Ильмир Ильдусович ауд. 108 ГК | P22: Судоустройство и правоохранительные органы Виноградов Никита Владиславович ауд. 303 | R22: 10:00-11:30 | S22: 2
B23: 12:05-13:35 | C23: 3 | D23: Финансы, денежное обращение и кредит Блесткина Ольга Владимировна ауд. 321 ГК | E23: Основы бухгалтерского учета Протасова Людмила Валерьевна ауд. 107 | F23: Дизайн-проектирование Любиченко Анна Андреевна ауд. 323 ГК | H23: Информационное обеспечение логистических процессов Верилов Александр Анатольевич ауд. 319 ГК | I23: Мастер-класс с работодателем по специальности «Торговое дело» ООО «Топфранчайз» Протасова Марина Валерьевна Руководитель отдела разработки франшиз ауд. 213 ГК | J23: Правовое и документационное обеспечение контрольно-надзорной деятельности в финансовой сфере Виноградов Никита Владиславович ауд. 303 | K23: Конституционное право России Рянжина Юлия Андреевна ауд. 201 | L23: История России Григорян Виталий Дмитриевич ауд. 312 | M23: Современные программы и технологии воспитания обучающихся начальных классов Глущенко Марина Валерьевна ауд. 110 | O23: Иностранный язык в профессиональной деятельности Макеев Данила Сергеевич ауд. 316 ГК | P23: Теория государства и права Тофан Алина Васильевна ауд. 204 | R23: 12:05-13:35 | S23: 3
B24: 13:45-15:15 | C24: 4 | D24: Иностранный язык в профессиональной деятельности Кармалинская Мария Дмитриевна ауд. 310 | F24: История Григорян Виталий Дмитриевич ауд. 312 | G24: Теоретические и методические основы физического воспитания и развития детей раннего и дошкольного возраста Глущенко Марина Валерьевна ауд. 110 | H24: Основы бережливого производства Петракова Екатерина Валерьевна ауд. 206 | I24: Основы бережливого производства Блесткина Ольга Владимировна ауд. 321 ГК | J24: История России Винокур Константин Владимирович ауд. 315 ГК | M24: Физическая культура Наташкин Степан Алексеевич ауд. Спортзал | O24: Информационные технологии Туркин Дмитрий Валерьевич ауд. 109 ГК | R24: 13:45-15:15 | S24: 4
B25: 15:25-16:55 | C25: 5 | D25: Русский язык и культура речи Митерова Евгения Анатольевна ауд. 108 | G25: Основы педагогики Глущенко Марина Валерьевна ауд. 110 | H25: Основы бережливого производства Петракова Екатерина Валерьевна ауд. 206 | I25: Основы бережливого производства Блесткина Ольга Владимировна ауд. 321 ГК | J25: Физическая культура Наташкин Степан Алексеевич ауд. Спортзал | O25: Физическая культура Заборских Артём Эдуардович ауд. Спортзал | R25: 15:25-16:55 | S25: 5
A26: ='4к 9 кл, 3к 11 кл'!A26:A30 -> Пятница 04.09.2026 | B26: 8:20-09:50 | C26: 1 | E26: Русский язык и культура речи Митерова Евгения Анатольевна ауд. 108 | K26: Теория государства и права Тофан Алина Васильевна ауд. 204 | Q26: ='4к 9 кл, 3к 11 кл'!A26:A30 -> Пятница 04.09.2026 | R26: 8:20-09:50 | S26: 1
B27: 10:00-11:30 | C27: 2 | D27: Основы предпринимательской деятельности Гужов Виктор Владимирович ауд. 316 ГК | E27: Основы бережливого производства Блесткина Ольга Владимировна ауд. 321 ГК | H27: Иностранный язык в профессиональной деятельности Ялышева Александра Геннадьевна ауд. 119 ГК | I27: Прикладные компьютерные программы в профессиональной деятельности Шамова Анастасия Владимировна ауд. 521 ГК | K27: История России Григорян Виталий Дмитриевич ауд. 312 | L27: Цели и задачи рекламных и коммуникационных кампаний, акций и мероприятий Ларионов Даниил Александрович ауд. 305 | N27: Физическая культура/Адаптивная физическая культура Заборских Артём Эдуардович ауд. Спортзал | P27: Уголовный процесс Тофан Алина Васильевна ауд. 204 | R27: 10:00-11:30 | S27: 2
B28: 12:05-13:35 | C28: 3 | D28: Основы предпринимательской деятельности Гужов Виктор Владимирович ауд. 316 ГК | E28: Статистика Блесткина Ольга Владимировна ауд. 321 ГК | F28: Психология общения Набиуллина Диляра Альбертовна ауд. 102 | H28: Мастер-класс с работодателем для специальности «Логистика» ГК "АЛЬФАРМА-М" Баканов Александр Николаевич Руководитель компаний в сфере здравоохранения, логистики и оптовой торговли, заместитель председателя комитета по здравоохранению партии «Новые люди». ауд. 315 ГК | I28: Прикладные компьютерные программы в профессиональной деятельности Шамова Анастасия Владимировна ауд. 521 ГК | K28: История России Григорян Виталий Дмитриевич ауд. 312 | L28: Анализ целевой аудитории, рынка и конкурентов Ларионов Даниил Александрович ауд. 305 | N28: Мастер-класс с работодателем по специальности «Специалист по технической эксплуатации и сопровождению информационных систем», «Техник по защите информации», «Компьютерные системы и комплексы», «Разработчик веб-приложений», «Программист» Государственная Корпорация по атомной энергии «РосАтом» Машиностроительный дивизион Дмитрий Морозов Руководитель Интеграция ИИ в управление бизнес процессов ауд. 117 ГК | O28: Мастер-класс с работодателем по специальности «Специалист по технической эксплуатации и сопровождению информационных систем», «Техник по защите информации», «Компьютерные системы и комплексы», «Разработчик веб-приложений», «Программист» Государственная Корпорация по атомной энергии «РосАтом» Машиностроительный дивизион Дмитрий Морозов Руководитель Интеграция ИИ в управление бизнес процессов ауд. 117 ГК | P28: Теория государства и права Тофан Алина Васильевна ауд. 204 | R28: 12:05-13:35 | S28: 3
B29: 13:45-15:15 | C29: 4 | D29: Финансы организации Блесткина Ольга Владимировна ауд. 321 ГК | F29: Иностранный язык в профессиональной деятельности Макеев Данила Сергеевич ауд. 319 ГК | G29: Русский язык и культура профессиональной коммуникации педагога Гарманова Анна Юрьевна ауд. 322 ГК | H29: Информационное обеспечение логистических процессов Верилов Александр Анатольевич ауд. 320 ГК | I29: Русский язык и культура речи Митерова Евгения Анатольевна ауд. 108 | K29: Уголовный процесс Тофан Алина Васильевна ауд. 204 | L29: Цели и задачи рекламных и коммуникационных кампаний, акций и мероприятий Ларионов Даниил Александрович ауд. 305 | N29: Операционные системы Сулейманов Ильмир Ильдусович ауд. 108 ГК | O29: Информационные технологии Туркин Дмитрий Валерьевич ауд. 109 ГК | R29: 13:45-15:15 | S29: 4
B30: 15:25-16:55 | C30: 5 | D30: Финансы, денежное обращение и кредит Блесткина Ольга Владимировна ауд. 321 ГК | F30: Психология общения Набиуллина Диляра Альбертовна ауд. 102 | G30: Русский (Родной) язык и культура профессиональной коммуникации Гарманова Анна Юрьевна ауд. 322 ГК | H30: Логистика закупок Верилов Александр Анатольевич ауд. 320 ГК | K30: Теория государства и права Тофан Алина Васильевна ауд. 204 | L30: Анализ целевой аудитории, рынка и конкурентов Ларионов Даниил Александрович ауд. 305 | N30: Иностранный язык в профессиональной деятельности Макеев Данила Сергеевич ауд. 319 ГК | O30: Русский язык и культура речи Митерова Евгения Анатольевна ауд. 108 | R30: 15:25-16:55 | S30: 5
A31: ='4к 9 кл, 3к 11 кл'!A31:A35 -> Суббота 05.09.2026 | B31: 8:20-09:50 | C31: 1 | E31: Основы бережливого производства Блесткина Ольга Владимировна ауд. 310 | H31: Логистика закупок Верилов Александр Анатольевич ауд. 320 ГК | I31: Организация торгово-сбытовой деятельности на внутреннем и внешнем рынках Репина Ольга Владимировна ауд. 201 | M31: Теоретические основы организации обучения в начальных классах Гарманова Анна Юрьевна ауд. 208 | Q31: ='4к 9 кл, 3к 11 кл'!A31:A35 -> Суббота 05.09.2026 | R31: 8:20-09:50 | S31: 1
B32: 10:00-11:30 | C32: 2 | E32: Экономика организации Блесткина Ольга Владимировна ауд. 310 | F32: Математика Козлова Ольга Викторовна ауд. 104 | H32: Складская логистика Верилов Александр Анатольевич ауд. 320 ГК | I32: Организация торгово-сбытовой деятельности на внутреннем и внешнем рынках Репина Ольга Владимировна ауд. 201 | L32: Цели и задачи рекламных и коммуникационных кампаний, акций и мероприятий Ларионов Даниил Александрович ауд. 312 | M32: История России Гоголев Николай Борисович ауд. 119 ГК | R32: 10:00-11:30 | S32: 2
B33: 12:05-13:35 | C33: 3 | D33: Финансы организации Блесткина Ольга Владимировна ауд. 310 | E33: Основы бухгалтерского учета Протасова Людмила Валерьевна ауд. 107 | F33: Математика Козлова Ольга Викторовна ауд. 104 | H33: Основы логистической деятельности Верилов Александр Анатольевич ауд. 320 ГК | L33: Анализ целевой аудитории, рынка и конкурентов Ларионов Даниил Александрович ауд. 312 | R33: 12:05-13:35 | S33: 3
B34: 13:45-15:15 | C34: 4 | D34: Основы бережливого производства Блесткина Ольга Владимировна ауд. 310 | E34: Основы бухгалтерского учета Протасова Людмила Валерьевна ауд. 107 | F34: Основы проектной и компьютерной графики Любиченко Анна Андреевна ауд. 314 | H34: История России Гоголев Николай Борисович ауд. 119 ГК | L34: Анализ целевой аудитории, рынка и конкурентов Ларионов Даниил Александрович ауд. 312 | R34: 13:45-15:15 | S34: 4
B35: 15:25-16:55 | C35: 5 | D35: История России Гоголев Николай Борисович ауд. 119 ГК | F35: Дизайн-проектирование Любиченко Анна Андреевна ауд. 314 | R35: 15:25-16:55 | S35: 5

Sheet 2к 11 кл, 2к 9 кл
A1: День недели | B1: Время | C1: Пара | D1: ИСП/П-25-11 | E1: ПВНК-25-11 | F1: ФК-25-11 | G1: ДИЗ-25-11 | H1: ИСП/Р-25-09 | I1: ИСП/П-25-09.1 | J1: ИСП/П-25-09.2 | K1: РЕК 25-09.1 | L1: РЕК 25-09.2 | M1: ЮР/са 25-09.1 | N1: ТД 25-09.2 | O1: ОДЛ 25-09.1 | P1: День недели | Q1: Время | R1: Пара
D2: Специальность: Информационные системы и программирование [09.02.07] Программист | E2: Специальность: Преподавание в начальных классах [44.02.02] Базовая | F2: Специальность: Физическая культура [49.02.01] Базовая | G2: Специальность: Дизайн (по отраслям) [54.02.01] Базовая | H2: Специальность: Информационные системы и программирование [09.02.07] Разработчик веб и мультимедийных приложений | I2: Специальность: Информационные системы и программирование [09.02.07] Программист | J2: Специальность: Информационные системы и программирование [09.02.07] Программист | K2: Специальность: Реклама [42.02.01] Базовая | L2: Специальность: Реклама [42.02.01] Базовая | M2: Специальность: Юриспруденция [40.02.04] Базовая | N2: Специальность: Торговое дело [38.02.08] Базовая | O2: Специальность: Операционная деятельность в логистике [38.02.03] Базовая
D3: к/о/к ИСП/п 25-11 | E3: к/о/к ПВНК 25-11 | F3: к/о/к ФК 25-11 | G3: к/о/к ДИЗ 25-11 | H3: к/о/к ИСП/р 25-09 | I3: к/о/к ИСП/п 25-09.1 | J3: к/о/к ИСП/п 25-09.2 | K3: к/о/к РЕК 25-09.1 | L3: к/о/к РЕК 25-09.2 | M3: к/о/к ЮР/са 25-09 | N3: к/о/к ТД 25-09.2 | O3: к/о/к ОДЛ 25-09
D4: 20 | E4: 8 | F4: 14 | G4: 11 | H4: 29 | I4: 31 | J4: 29 | K4: 34 | L4: 35 | M4: 35 | N4: 33 | O4: 30
D5: ='4к 9 кл, 3к 11 кл'!D5:G5 -> 1 неделя
A6: Понедельник 31.08.2026 | B6: 8:20-09:50 | C6: 1 | P6: ='4к 9 кл, 3к 11 кл'!A6:A10 -> Понедельник 31.08.2026 | Q6: 8:20-09:50 | R6: 1
B7: 10:00-11:30 | C7: 2 | Q7: 10:00-11:30 | R7: 2
B8: 12:05-13:35 | C8: 3 | Q8: 12:05-13:35 | R8: 3
B9: 13:45-15:15 | C9: 4 | Q9: 13:45-15:15 | R9: 4
B10: 15:25-16:55 | C10: 5 | Q10: 15:25-16:55 | R10: 5
A11: ='4к 9 кл, 3к 11 кл'!A11:A15 -> Вторник 01.09.2026 | B11: 8:20-09:50 | C11: 1 | P11: ='4к 9 кл, 3к 11 кл'!A11:A15 -> Вторник 01.09.2026 | Q11: 8:20-09:50 | R11: 1
B12: 10:00-11:30 | C12: 2 | Q12: 10:00-11:30 | R12: 2
B13: 12:05-13:35 | C13: 3 | Q13: 12:05-13:35 | R13: 3
B14: 13:45-15:15 | C14: 4 | D14: Основы проектирования баз данных Сулейманов Ильмир Ильдусович ауд. 108 ГК | E14: Теоретические и методические основы преподавания иностранного языка в начальной школе Ялышева Александра Геннадьевна ауд. 312 | F14: Возрастная анатомия, физиология и гигиена Гордиенко Ольга Николаевна ауд. 119 ГК | H14: Основы алгоритмизации и программирования Шамова Анастасия Владимировна ауд. 521 ГК | I14: Информационные технологии/Адаптивные информационные технологии Шамов Артём Варельевич ауд. 118 ГК | O14: История России Гоголев Николай Борисович ауд. 108 | Q14: 13:45-15:15 | R14: 4
B15: 15:25-16:55 | C15: 5 | D15: Основы проектирования баз данных Сулейманов Ильмир Ильдусович ауд. 108 ГК | E15: Теоретические и методические основы преподавания иностранного языка в начальной школе Ялышева Александра Геннадьевна ауд. 312 | F15: Методика обучения предмету "Физическая культура" Гордиенко Ольга Николаевна ауд. 119 ГК | I15: Основы алгоритмизации и программирования Шамова Анастасия Владимировна ауд. 521 ГК | O15: История России Гоголев Николай Борисович ауд. 108 | Q15: 15:25-16:55 | R15: 5
A16: Среда 02.09.2026 | B16: 8:20-09:50 | C16: 1 | I16: Иностранный язык в профессиональной деятельности Ялышева Александра Геннадьевна ауд. 322 ГК | N16: Русский язык и культура речи Митерова Евгения Анатольевна ауд. 108 | P16: ='4к 9 кл, 3к 11 кл'!A16:A20 -> Среда 02.09.2026 | Q16: 8:20-09:50 | R16: 1
B17: 10:00-11:30 | C17: 2 | I17: Основы алгоритмизации и программирования Шамова Анастасия Владимировна ауд. 521 ГК | J17: Иностранный язык в профессиональной деятельности Ялышева Александра Геннадьевна ауд. 322 ГК | K17: Анализ целевой аудитории, рынка и конкурентов Ларионов Даниил Александрович ауд. ВЕБИНАР | N17: Русский язык и культура речи Митерова Евгения Анатольевна ауд. 108 | Q17: 10:00-11:30 | R17: 2
B18: 12:05-13:35 | C18: 3 | G18: Иностранный язык в профессиональной деятельности Макеев Данила Сергеевич ауд. 319 ГК | I18: Основы алгоритмизации и программирования Шамова Анастасия Владимировна ауд. 521 ГК | J18: Физическая культура/Адаптивная физическая культура Заборских Артём Эдуардович ауд. Спортзал | K18: Цели и задачи рекламных и коммуникационных кампаний, акций и мероприятий Ларионов Даниил Александрович ауд. ВЕБИНАР | O18: Русский язык и культура речи Митерова Евгения Анатольевна ауд. 108 | Q18: 12:05-13:35 | R18: 3
B19: 13:45-15:15 | C19: 4 | D19: Численные методы Абрамова Татьяна Викторовна ауд. 202 ГК | E19: Основы организации внеурочной деятельности Глущенко Марина Валерьевна ауд. 314 | F19: Теоретические и прикладные аспекты методической работы в области физической культуры и спорта Степаненко Юлия Витальевна ауд. 307 | G19: Выполнение дизайнерских проектов в материале Лебедева Катерина Владимировна ауд. 308 | H19: Информационные технологии/Адаптивные информационные технологии Шамов Артём Варельевич ауд. 507 ГК | J19: Операционные системы и среды Сулейманов Ильмир Ильдусович ауд. 108 ГК | K19: Цели и задачи рекламных и коммуникационных кампаний, акций и мероприятий Ларионов Даниил Александрович ауд. ВЕБИНАР | Q19: 13:45-15:15 | R19: 4
B20: 15:25-16:55 | C20: 5 | D20: Менеджмент в профессиональной деятельности Гужов Виктор Владимирович ауд. 320 ГК | E20: Основы организации внеурочной деятельности Глущенко Марина Валерьевна ауд. 314 | F20: Методика преподавания по дополнительным общеразвивающим программам в области физической культуры спорта Степаненко Юлия Витальевна ауд. 307 | G20: Материаловедение Лебедева Катерина Владимировна ауд. 308 | H20: Элементы высшей математики Абрамова Татьяна Викторовна ауд. 202 ГК | J20: Операционные системы и среды Сулейманов Ильмир Ильдусович ауд. 108 ГК | K20: Основы композиции, рисунка, живописи в рекламе Васьковская Татьяна Александровна ауд. ВЕБИНАР | Q20: 15:25-16:55 | R20: 5
A21: ='4к 9 кл, 3к 11 кл'!A21:A25 -> Четверг 03.09.2026 | B21: 8:20-09:50 | C21: 1 | G21: Основы конструкторско-технологического обеспечения дизайна Лебедева Катерина Владимировна ауд. 308 | J21: Основы алгоритмизации и программирования Шамова Анастасия Владимировна ауд. 521 ГК | M21: Теория государства и права Тофан Алина Васильевна ауд. 204 | P21: ='4к 9 кл, 3к 11 кл'!A21:A25 -> Четверг 03.09.2026 | Q21: 8:20-09:50 | R21: 1
B22: 10:00-11:30 | C22: 2 | F22: Организационно-методические основы физкультурно-спортивной работы Заборских Артём Эдуардович ауд. Спортзал | G22: Выполнение дизайнерских проектов в материале Лебедева Катерина Владимировна ауд. 308 | J22: Основы алгоритмизации и программирования Шамова Анастасия Владимировна ауд. 521 ГК | M22: Уголовный процесс Тофан Алина Васильевна ауд. 204 | Q22: 10:00-11:30 | R22: 2
B23: 12:05-13:35 | C23: 3 | D23: Физическая культура/Адаптивная физическая культура Заборских Артём Эдуардович ауд. Спортзал | F23: Физическая культура Гордиенко Ольга Николаевна ауд.спортзал | G23: Выполнение дизайнерских проектов в материале Лебедева Катерина Владимировна ауд. 308 | J23: Основы алгоритмизации и программирования Шамова Анастасия Владимировна ауд. 521 ГК | K23: Анализ целевой аудитории, рынка и конкурентов Ларионов Даниил Александрович ауд. ВЕБИНАР | Q23: 12:05-13:35 | R23: 3
B24: 13:45-15:15 | C24: 4 | D24: Численные методы Абрамова Татьяна Викторовна ауд. 202 ГК | F24: Методика обучения предмету "Физическая культура" Гордиенко Ольга Николаевна ауд. 119 ГК | G24: Основы конструкторско-технологического обеспечения дизайна Лебедева Катерина Владимировна ауд. 308 | H24: Операционные системы и среды Сулейманов Ильмир Ильдусович ауд. 108 ГК | I24: Физическая культура/Адаптивная физическая культура Заборских Артём Эдуардович ауд. Спортзал | K24: Анализ целевой аудитории, рынка и конкурентов Ларионов Даниил Александрович ауд. ВЕБИНАР | N24: Организация торгово-сбытовой деятельности на внутреннем и внешнем рынках Репина Ольга Владимировна ауд. 326 ГК | Q24: 13:45-15:15 | R24: 4
B25: 15:25-16:55 | C25: 5 | D25: Инструментальные средства разработки программного обеспечения Шамова Анастасия Владимировна ауд. 521 ГК | F25: Возрастная анатомия, физиология и гигиена Гордиенко Ольга Николаевна ауд. 119 ГК | G25: Живопись с основами цветоведения Лебедева Катерина Владимировна ауд. 308 | H25: Элементы высшей математики Абрамова Татьяна Викторовна ауд. 202 ГК | I25: Операционные системы и среды Сулейманов Ильмир Ильдусович ауд. 108 ГК | K25: Цели и задачи рекламных и коммуникационных кампаний, акций и мероприятий Ларионов Даниил Александрович ауд. ВЕБИНАР | O25: Основы логистической деятельности Верилов Александр Анатольевич ауд. 319 ГК | Q25: 15:25-16:55 | R25: 5
A26: ='4к 9 кл, 3к 11 кл'!A26:A30 -> Пятница 04.09.2026 | B26: 8:20-09:50 | C26: 1 | E26: Теоретические и методические основы деятельности классного руководителя Глущенко Марина Валерьевна ауд. 110 | F26: Методика преподавания по дополнительным общеразвивающим программам в области физической культуры спорта Степаненко Юлия Витальевна ауд. 307 | I26: Информационные технологии/Адаптивные информационные технологии Шамов Артём Варельевич ауд. 118 ГК | K26: История России Григорян Виталий Дмитриевич ауд. ВЕБИНАР | P26: ='4к 9 кл, 3к 11 кл'!A26:A30 -> Пятница 04.09.2026 | Q26: 8:20-09:50 | R26: 1
B27: 10:00-11:30 | C27: 2 | D27: Экономика отрасли Митерова Елена Валерьевна ауд. 105 | E27: Основы организации внеурочной деятельности Глущенко Марина Валерьевна ауд. 110 | F27: Организация и методика проведения физкультурно-оздоровительных занятий и занятий по виду спорта с населением различных возрастных групп Степаненко Юлия Витальевна ауд. 307 | I27: Элементы высшей математики Абрамова Татьяна Викторовна ауд. 202 ГК | J27: Информационные технологии/Адаптивные информационные технологии Шамов Артём Варельевич ауд. 118 ГК | K27: Основы бережливого производства Петракова Екатерина Валерьевна ауд. ВЕБИНАР | Q27: 10:00-11:30 | R27: 2
B28: 12:05-13:35 | C28: 3 | D28: Экономика отрасли Митерова Елена Валерьевна ауд. 105 | E28: Основы организации внеурочной деятельности Глущенко Марина Валерьевна ауд. 110 | F28: Организационно-методические основы физкультурно-спортивной работы Заборских Артём Эдуардович ауд. 314 | G28: Выполнение дизайнерских проектов в материале Лебедева Катерина Владимировна ауд. ВЕБИНАР | I28: Элементы высшей математики Абрамова Татьяна Викторовна ауд. 202 ГК | J28: Информационные технологии/Адаптивные информационные технологии Шамов Артём Варельевич ауд. 118 ГК | K28: Основы бережливого производства Петракова Екатерина Валерьевна ауд. ВЕБИНАР | Q28: 12:05-13:35 | R28: 3
B29: 13:45-15:15 | C29: 4 | D29: Иностранный язык в профессиональной деятельности Ялышева Александра Геннадьевна ауд. 119 ГК | E29: Физическая культура Гордиенко Ольга Николаевна ауд. Спортзал | F29: Организационно-методические основы физкультурно-спортивной работы Заборских Артём Эдуардович ауд. 314 | G29: Выполнение дизайнерских проектов в материале Лебедева Катерина Владимировна ауд. ВЕБИНАР | H29: Основы алгоритмизации и программирования Шамова Анастасия Владимировна ауд. 521 ГК | L29: Основы бережливого производства Петракова Екатерина Валерьевна ауд. ВЕБИНАР | Q29: 13:45-15:15 | R29: 4
B30: 15:25-16:55 | C30: 5 | D30: Инструментальные средства разработки программного обеспечения Шамова Анастасия Владимировна ауд. 521 ГК | E30: Теоретические и методические основы преподавания иностранного языка в начальной школе Ялышева Александра Геннадьевна ауд. 119 ГК | F30: Методика обучения предмету "Физическая культура" Гордиенко Ольга Николаевна ауд. 314 | G30: Живопись с основами цветоведения Лебедева Катерина Владимировна ауд. ВЕБИНАР | H30: Физическая культура/Адаптивная физическая культура Заборских Артём Эдуардович ауд. Спортзал | L30: Основы бережливого производства Петракова Екатерина Валерьевна ауд. ВЕБИНАР | Q30: 15:25-16:55 | R30: 5
A31: Суббота 05.09.2026 | B31: 8:20-09:50 | C31: 1 | D31: Технология разработки программного обеспечения Шамова Анастасия Владимировна ауд. 520 ГК | E31: Иностранный язык в профессиональной деятельности Ялышева Александра Геннадьевна ауд. 303 | P31: ='4к 9 кл, 3к 11 кл'!A31:A35 -> Суббота 05.09.2026 | Q31: 8:20-09:50 | R31: 1
B32: 10:00-11:30 | C32: 2 | D32: Основы проектирования баз данных Сулейманов Ильмир Ильдусович ауд. 108 ГК | E32: Русский язык с методикой преподавания Гарманова Анна Юрьевна ауд. 208 | Q32: 10:00-11:30 | R32: 2
B33: 12:05-13:35 | C33: 3 | E33: Русский язык с методикой преподавания Гарманова Анна Юрьевна ауд. 208 | Q33: 12:05-13:35 | R33: 3
B34: 13:45-15:15 | C34: 4 | H34: Русский язык и культура речи Гарманова Анна Юрьевна ауд. 208 | N34: Организация торгово-сбытовой деятельности на внутреннем и внешнем рынках Репина Ольга Владимировна ауд. 201 | Q34: 13:45-15:15 | R34: 4
B35: 15:25-16:55 | C35: 5 | H35: Основы алгоритмизации и программирования Шамова Анастасия Владимировна ауд. 520 ГК | Q35: 15:25-16:55 | R35: 5

Sheet 1к 11 кл
A1: День недели | B1: Время | C1: Пара | D1: ТОРАС 26-11 | E1: ВЕБ 26-11 | F1: ИРПТИИ 26-11 | G1: ТЭСИС 26-11 | H1: РУПО 26-11 | I1: КВД 26-11 | J1: ТИК 26-11 | K1: ФК 26-11 | L1: День недели | M1: Время | N1: Пара
D2: Специальность: Техническое обслуживание и ремонт автотранспортных средств [23.02.07] Базовая | E2: Специальность: Веб-разработка [09.02.09] Базовая | F2: Специальность: Интеграция решений с применением технологий искусственного интеллекта [09.02.13] Базовая | G2: Специальность: Техническая эксплуатация и сопровождение информационных систем [09.02.12] Базовая | H2: Специальность: Разработка и управление программным обеспечением [09.02.11] Базовая | I2: Специальность: Конгрессно-выставочная деятельность [38.02.09] Базовая | J2: Специальность: Технологии индустрии красоты [43.02.17] Базовая | K2: Специальность: Физическая культура [49.02.01] Базовая
D4: 25 | E4: 25 | F4: 25 | G4: 25 | H4: 25 | I4: 25 | J4: 25 | K4: 25
D5: ='4к 9 кл, 3к 11 кл'!D5:G5 -> 1 неделя
A6: ='4к 9 кл, 3к 11 кл'!A6:A10 -> Понедельник 31.08.2026 | B6: 8:20-09:50 | C6: 1 | L6: ='4к 9 кл, 3к 11 кл'!A6:A10 -> Понедельник 31.08.2026 | M6: 8:20-09:50 | N6: 1
B7: 10:00-11:30 | C7: 2 | M7: 10:00-11:30 | N7: 2
B8: 12:05-13:35 | C8: 3 | M8: 12:05-13:35 | N8: 3
B9: 13:45-15:15 | C9: 4 | M9: 13:45-15:15 | N9: 4
B10: 15:25-16:55 | C10: 5 | M10: 15:25-16:55 | N10: 5
A11: Вторник 01.09.2026 | B11: 8:20-09:50 | C11: 1 | L11: ='4к 9 кл, 3к 11 кл'!A11:A15 -> Вторник 01.09.2026 | M11: 8:20-09:50 | N11: 1
B12: 10:00-11:30 | C12: 2 | M12: 10:00-11:30 | N12: 2
B13: 12:05-13:35 | C13: 3 | M13: 12:05-13:35 | N13: 3
B14: 13:45-15:15 | C14: 4 | M14: 13:45-15:15 | N14: 4
B15: 15:25-16:55 | C15: 5 | M15: 15:25-16:55 | N15: 5
A16: Среда 02.09.2026 | B16: 8:20-09:50 | C16: 1 | G16: Базы данных Соломин Максим Сергеевич ауд. 531 ГК | H16: Основы работы с информацией Акишин Максим Витальевич ауд. 210 | K16: Базовые и новые виды физкультурно-спортивной деятельности: гимнастика Гордиенко Ольга Николаевна ауд. 119 ГК | L16: ='4к 9 кл, 3к 11 кл'!A16:A20 -> Среда 02.09.2026 | M16: 8:20-09:50 | N16: 1
B17: 10:00-11:30 | C17: 2 | E17: Основы проектирования баз данных Сулейманов Ильмир Ильдусович ауд. 108 ГК | G17: Базы данных Соломин Максим Сергеевич ауд. 531 ГК | H17: Основы информационной безопасности Акишин Максим Витальевич ауд. 210 | K17: Базовые и новые виды физкультурно-спортивной деятельности: легкая атлетика Гордиенко Ольга Николаевна ауд. 119 ГК | M17: 10:00-11:30 | N17: 2
B18: 12:05-13:35 | C18: 3 | E18: Основы проектирования баз данных Сулейманов Ильмир Ильдусович ауд. 108 ГК | F18: Иностранный язык в профессиональной деятельности Ялышева Александра Геннадьевна ауд. 322 ГК | I18: Мастер-класс с работодателем по специальности «Конгрессно-выставочная деятельность» ПО АНО «Академия МАКСИМУМ» Хвостов Александр Директор по связям с образовательным сообществом Организатор выставки «Навигатор поступления» ауд. 105 | K18: Анатомия и физиология человека Гордиенко Ольга Николаевна ауд. 119 ГК | M18: 12:05-13:35 | N18: 3
B19: 13:45-15:15 | C19: 4 | E19: Компьютерные сети Чагиров Артур Олегович ауд. 109 ГК | M19: 13:45-15:15 | N19: 4
B20: 15:25-16:55 | C20: 5 | E20: История России Григорян Виталий Дмитриевич ауд. 312 | M20: 15:25-16:55 | N20: 5
A21: Четверг 03.09.2026 | B21: 8:20-09:50 | C21: 1 | F21: Элементы высшей математики Абрамова Татьяна Викторовна ауд. 202 ГК | H21: Операционные системы и среды Сулейманов Ильмир Ильдусович ауд. 108 ГК | K21: Базовые и новые виды физкультурно-спортивной деятельности: туризм Степаненко Юлия Витальевна ауд. 307 | L21: ='4к 9 кл, 3к 11 кл'!A21:A25 -> Четверг 03.09.2026 | M21: 8:20-09:50 | N21: 1
B22: 10:00-11:30 | C22: 2 | D22: Физическая культура Наташкин Степан Алексеевич ауд. спортзал | F22: Элементы высшей математики Абрамова Татьяна Викторовна ауд. 202 ГК | H22: Основы информационной безопасности Акишин Максим Витальевич ауд. 210 | K22: Базовые и новые виды физкультурно-спортивной деятельности: спортивные игры Степаненко Юлия Витальевна ауд. 307 | M22: 10:00-11:30 | N22: 2
B23: 12:05-13:35 | C23: 3 | D23: Физическая культура Наташкин Степан Алексеевич ауд. Спортзал | E23: Основы проектирования баз данных Сулейманов Ильмир Ильдусович ауд. 108 ГК | F23: Мастер-класс с работодателем по специальности «Специалист по работе с искусственным интеллектом» SEO Performance Agency Мятов Михаил Александрович Совладелец, Инвестор в ИИ ауд. 117 ГК | H23: Архитектура аппаратных средств Туркин Дмитрий Валерьевич ауд. 109 ГК | K23: Базовые и новые виды физкультурно-спортивной деятельности: спортивные игры Степаненко Юлия Витальевна ауд. 307 | M23: 12:05-13:35 | N23: 3
B24: 13:45-15:15 | C24: 4 | E24: Проектирование информационных ресурсов Чагиров Артур Олегович ауд. 505 ГК | M24: 13:45-15:15 | N24: 4
B25: 15:25-16:55 | C25: 5 | M25: 15:25-16:55 | N25: 5
